Workbook

Sheet class_view
A1: Class Overview
A3: Selected class | B3: tanker
A5: Categories | D5: Base Stats | G5: Attributes | J5: Abilities | M5: Meta
A6: base | B6: =IFERROR(VLOOKUP($B$3,categories!$A:$D,2,FALSE),"") -> 90 | D6: =INDEX(base_stats!$1:$1,2) -> armor | E6: =INDEX(base_stats!$2:$9,MATCH($B$3,base_stats!$A$2:$A$9,0),2) -> 3 | G6: =INDEX(attributes!$1:$1,2) -> ability_power | H6: =INDEX(attributes!$2:$9,MATCH($B$3,attributes!$A$2:$A$9,0),2) -> 1 | J6: =INDEX(abilities!$1:$1,2) -> arrow_shot | K6: =INDEX(abilities!$2:$9,MATCH($B$3,abilities!$A$2:$A$9,0),2) -> 1 | M6: preferredAttributeWeightMultiplier | N6: =IFERROR(VLOOKUP("preferredAttributeWeightMultiplier",meta!$A:$B,2,FALSE),"") -> 30
A7: attribute | B7: =IFERROR(VLOOKUP($B$3,categories!$A:$D,3,FALSE),"") -> 10 | D7: =INDEX(base_stats!$1:$1,3) -> armor_toughness | E7: =INDEX(base_stats!$2:$9,MATCH($B$3,base_stats!$A$2:$A$9,0),3) -> 3 | G7: =INDEX(attributes!$1:$1,3) -> amphibious | H7: =INDEX(attributes!$2:$9,MATCH($B$3,attributes!$A$2:$A$9,0),3) -> 1 | J7: =INDEX(abilities!$1:$1,3) -> battle_strength | K7: =INDEX(abilities!$2:$9,MATCH($B$3,abilities!$A$2:$A$9,0),3) -> 1 | M7: preferredAbilityWeightMultiplier | N7: =IFERROR(VLOOKUP("preferredAbilityWeightMultiplier",meta!$A:$B,2,FALSE),"") -> 9
A8: ability | B8: =IFERROR(VLOOKUP($B$3,categories!$A:$D,4,FALSE),"") -> 10 | D8: =INDEX(base_stats!$1:$1,4) -> damage | E8: =INDEX(base_stats!$2:$9,MATCH($B$3,base_stats!$A$2:$A$9,0),4) -> 1 | G8: =INDEX(attributes!$1:$1,4) -> bane_of_arthropods | H8: =INDEX(attributes!$2:$9,MATCH($B$3,attributes!$A$2:$A$9,0),4) -> 1 | J8: =INDEX(abilities!$1:$1,4) -> battlefield_medic | K8: =INDEX(abilities!$2:$9,MATCH($B$3,abilities!$A$2:$A$9,0),4) -> 1
D9: =INDEX(base_stats!$1:$1,5) -> hp | E9: =INDEX(base_stats!$2:$9,MATCH($B$3,base_stats!$A$2:$A$9,0),5) -> 3 | G9: =INDEX(attributes!$1:$1,5) -> blazing_protection | H9: =INDEX(attributes!$2:$9,MATCH($B$3,attributes!$A$2:$A$9,0),5) -> 4 | J9: =INDEX(abilities!$1:$1,5) -> berserker | K9: =INDEX(abilities!$2:$9,MATCH($B$3,abilities!$A$2:$A$9,0),5) -> 1
D10: =INDEX(base_stats!$1:$1,6) -> knockback | E10: =INDEX(base_stats!$2:$9,MATCH($B$3,base_stats!$A$2:$A$9,0),6) -> 1 | G10: =INDEX(attributes!$1:$1,6) -> bubbling | H10: =INDEX(attributes!$2:$9,MATCH($B$3,attributes!$A$2:$A$9,0),6) -> 1 | J10: =INDEX(abilities!$1:$1,6) -> blaze_attack | K10: =INDEX(abilities!$2:$9,MATCH($B$3,abilities!$A$2:$A$9,0),6) -> 1
D11: =INDEX(base_stats!$1:$1,7) -> knockback_resist | E11: =INDEX(base_stats!$2:$9,MATCH($B$3,base_stats!$A$2:$A$9,0),7) -> 1 | G11: =INDEX(attributes!$1:$1,7) -> chain_lightning | H11: =INDEX(attributes!$2:$9,MATCH($B$3,attributes!$A$2:$A$9,0),7) -> 1 | J11: =INDEX(abilities!$1:$1,7) -> bloodlust | K11: =INDEX(abilities!$2:$9,MATCH($B$3,abilities!$A$2:$A$9,0),7) -> 1
D12: =INDEX(base_stats!$1:$1,8) -> speed | E12: =INDEX(base_stats!$2:$9,MATCH($B$3,base_stats!$A$2:$A$9,0),8) -> 1 | G12: =INDEX(attributes!$1:$1,8) -> charisma | H12: =INDEX(attributes!$2:$9,MATCH($B$3,attributes!$A$2:$A$9,0),8) -> 1 | J12: =INDEX(abilities!$1:$1,8) -> body_block | K12: =INDEX(abilities!$2:$9,MATCH($B$3,abilities!$A$2:$A$9,0),8) -> 4
G13: =INDEX(attributes!$1:$1,9) -> fire_resistance | H13: =INDEX(attributes!$2:$9,MATCH($B$3,attributes!$A$2:$A$9,0),9) -> 3.8 | J13: =INDEX(abilities!$1:$1,9) -> cleanse_touch | K13: =INDEX(abilities!$2:$9,MATCH($B$3,abilities!$A$2:$A$9,0),9) -> 1
G14: =INDEX(attributes!$1:$1,10) -> firefang | H14: =INDEX(attributes!$2:$9,MATCH($B$3,attributes!$A$2:$A$9,0),10) -> 1 | J14: =INDEX(abilities!$1:$1,10) -> crossbow | K14: =INDEX(abilities!$2:$9,MATCH($B$3,abilities!$A$2:$A$9,0),10) -> 1
G15: =INDEX(attributes!$1:$1,11) -> frost_fang | H15: =INDEX(attributes!$2:$9,MATCH($B$3,attributes!$A$2:$A$9,0),11) -> 1 | J15: =INDEX(abilities!$1:$1,11) -> dash | K15: =INDEX(abilities!$2:$9,MATCH($B$3,abilities!$A$2:$A$9,0),11) -> 1
G16: =INDEX(attributes!$1:$1,12) -> health_siphon | H16: =INDEX(attributes!$2:$9,MATCH($B$3,attributes!$A$2:$A$9,0),12) -> 2.5 | J16: =INDEX(abilities!$1:$1,12) -> defensive_aura | K16: =INDEX(abilities!$2:$9,MATCH($B$3,abilities!$A$2:$A$9,0),12) -> 4.8
G17: =INDEX(attributes!$1:$1,13) -> herding | H17: =INDEX(attributes!$2:$9,MATCH($B$3,attributes!$A$2:$A$9,0),13) -> 1 | J17: =INDEX(abilities!$1:$1,13) -> deflection | K17: =INDEX(abilities!$2:$9,MATCH($B$3,abilities!$A$2:$A$9,0),13) -> 4
G18: =INDEX(attributes!$1:$1,14) -> killer | H18: =INDEX(attributes!$2:$9,MATCH($B$3,attributes!$A$2:$A$9,0),14) -> 1 | J18: =INDEX(abilities!$1:$1,14) -> defusal | K18: =INDEX(abilities!$2:$9,MATCH($B$3,abilities!$A$2:$A$9,0),14) -> 7
G19: =INDEX(attributes!$1:$1,15) -> killexploder | H19: =INDEX(attributes!$2:$9,MATCH($B$3,attributes!$A$2:$A$9,0),15) -> 1 | J19: =INDEX(abilities!$1:$1,15) -> dragon_fireball | K19: =INDEX(abilities!$2:$9,MATCH($B$3,abilities!$A$2:$A$9,0),15) -> 1
G20: =INDEX(attributes!$1:$1,16) -> lifesteal | H20: =INDEX(attributes!$2:$9,MATCH($B$3,attributes!$A$2:$A$9,0),16) -> 1 | J20: =INDEX(abilities!$1:$1,16) -> elder_guardian_beam | K20: =INDEX(abilities!$2:$9,MATCH($B$3,abilities!$A$2:$A$9,0),16) -> 1
G21: =INDEX(attributes!$1:$1,17) -> lightningfang | H21: =INDEX(attributes!$2:$9,MATCH($B$3,attributes!$A$2:$A$9,0),17) -> 1 | J21: =INDEX(abilities!$1:$1,17) -> emergency_shield | K21: =INDEX(abilities!$2:$9,MATCH($B$3,abilities!$A$2:$A$9,0),17) -> 4
G22: =INDEX(attributes!$1:$1,18) -> linked_inventory | H22: =INDEX(attributes!$2:$9,MATCH($B$3,attributes!$A$2:$A$9,0),18) -> 1 | J22: =INDEX(abilities!$1:$1,18) -> ender_pearl_jump | K22: =INDEX(abilities!$2:$9,MATCH($B$3,abilities!$A$2:$A$9,0),18) -> 1
G23: =INDEX(attributes!$1:$1,19) -> magnetic | H23: =INDEX(attributes!$2:$9,MATCH($B$3,attributes!$A$2:$A$9,0),19) -> 1 | J23: =INDEX(abilities!$1:$1,19) -> evoker_fangs | K23: =INDEX(abilities!$2:$9,MATCH($B$3,abilities!$A$2:$A$9,0),19) -> 1
G24: =INDEX(attributes!$1:$1,20) -> muffled | H24: =INDEX(attributes!$2:$9,MATCH($B$3,attributes!$A$2:$A$9,0),20) -> 1 | J24: =INDEX(abilities!$1:$1,20) -> ghast_fireball | K24: =INDEX(abilities!$2:$9,MATCH($B$3,abilities!$A$2:$A$9,0),20) -> 1
G25: =INDEX(attributes!$1:$1,21) -> ore_scenting | H25: =INDEX(attributes!$2:$9,MATCH($B$3,attributes!$A$2:$A$9,0),21) -> 1 | J25: =INDEX(abilities!$1:$1,21) -> guardian_beam | K25: =INDEX(abilities!$2:$9,MATCH($B$3,abilities!$A$2:$A$9,0),21) -> 1
G26: =INDEX(attributes!$1:$1,22) -> pacifist | H26: =INDEX(attributes!$2:$9,MATCH($B$3,attributes!$A$2:$A$9,0),22) -> 2.8 | J26: =INDEX(abilities!$1:$1,22) -> guardian_intercept | K26: =INDEX(abilities!$2:$9,MATCH($B$3,abilities!$A$2:$A$9,0),22) -> 4
G27: =INDEX(attributes!$1:$1,23) -> pierce | H27: =INDEX(attributes!$2:$9,MATCH($B$3,attributes!$A$2:$A$9,0),23) -> 1 | J27: =INDEX(abilities!$1:$1,23) -> guardian_repulse | K27: =INDEX(abilities!$2:$9,MATCH($B$3,abilities!$A$2:$A$9,0),23) -> 4
G28: =INDEX(attributes!$1:$1,24) -> poison_fang | H28: =INDEX(attributes!$2:$9,MATCH($B$3,attributes!$A$2:$A$9,0),24) -> 1 | J28: =INDEX(abilities!$1:$1,24) -> healing_aura | K28: =INDEX(abilities!$2:$9,MATCH($B$3,abilities!$A$2:$A$9,0),24) -> 1
G29: =INDEX(attributes!$1:$1,25) -> poison_resistance | H29: =INDEX(attributes!$2:$9,MATCH($B$3,attributes!$A$2:$A$9,0),25) -> 3.8 | J29: =INDEX(abilities!$1:$1,25) -> healing_bottle | K29: =INDEX(abilities!$2:$9,MATCH($B$3,abilities!$A$2:$A$9,0),25) -> 1
G30: =INDEX(attributes!$1:$1,26) -> positive_effect_steal | H30: =INDEX(attributes!$2:$9,MATCH($B$3,attributes!$A$2:$A$9,0),26) -> 1 | J30: =INDEX(abilities!$1:$1,26) -> immunity_frame | K30: =INDEX(abilities!$2:$9,MATCH($B$3,abilities!$A$2:$A$9,0),26) -> 4
G31: =INDEX(attributes!$1:$1,27) -> regeneration | H31: =INDEX(attributes!$2:$9,MATCH($B$3,attributes!$A$2:$A$9,0),27) -> 4.2 | J31: =INDEX(abilities!$1:$1,27) -> last_stand_fury | K31: =INDEX(abilities!$2:$9,MATCH($B$3,abilities!$A$2:$A$9,0),27) -> 4
G32: =INDEX(attributes!$1:$1,28) -> rejuvenation | H32: =INDEX(attributes!$2:$9,MATCH($B$3,attributes!$A$2:$A$9,0),28) -> 1 | J32: =INDEX(abilities!$1:$1,28) -> life_gift | K32: =INDEX(abilities!$2:$9,MATCH($B$3,abilities!$A$2:$A$9,0),28) -> 1
G33: =INDEX(attributes!$1:$1,29) -> resistance | H33: =INDEX(attributes!$2:$9,MATCH($B$3,attributes!$A$2:$A$9,0),29) -> 4.6 | J33: =INDEX(abilities!$1:$1,29) -> lightning_strike | K33: =INDEX(abilities!$2:$9,MATCH($B$3,abilities!$A$2:$A$9,0),29) -> 1
G34: =INDEX(attributes!$1:$1,30) -> smite | H34: =INDEX(attributes!$2:$9,MATCH($B$3,attributes!$A$2:$A$9,0),30) -> 1 | J34: =INDEX(abilities!$1:$1,30) -> llama_spit | K34: =INDEX(abilities!$2:$9,MATCH($B$3,abilities!$A$2:$A$9,0),30) -> 1
G35: =INDEX(attributes!$1:$1,31) -> speed | H35: =INDEX(attributes!$2:$9,MATCH($B$3,attributes!$A$2:$A$9,0),31) -> 1 | J35: =INDEX(abilities!$1:$1,31) -> psychic_wall | K35: =INDEX(abilities!$2:$9,MATCH($B$3,abilities!$A$2:$A$9,0),31) -> 4
G36: =INDEX(attributes!$1:$1,32) -> strength | H36: =INDEX(attributes!$2:$9,MATCH($B$3,attributes!$A$2:$A$9,0),32) -> 1 | J36: =INDEX(abilities!$1:$1,32) -> retaliation_slow | K36: =INDEX(abilities!$2:$9,MATCH($B$3,abilities!$A$2:$A$9,0),32) -> 1
G37: =INDEX(attributes!$1:$1,33) -> sweeping_edge | H37: =INDEX(attributes!$2:$9,MATCH($B$3,attributes!$A$2:$A$9,0),33) -> 1 | J37: =INDEX(abilities!$1:$1,33) -> shadow_hands | K37: =INDEX(abilities!$2:$9,MATCH($B$3,abilities!$A$2:$A$9,0),33) -> 1
G38: =INDEX(attributes!$1:$1,34) -> totem | H38: =INDEX(attributes!$2:$9,MATCH($B$3,attributes!$A$2:$A$9,0),34) -> 3.6 | J38: =INDEX(abilities!$1:$1,34) -> shield_block | K38: =INDEX(abilities!$2:$9,MATCH($B$3,abilities!$A$2:$A$9,0),34) -> 4
G39: =INDEX(attributes!$1:$1,35) -> victim_siphon | H39: =INDEX(attributes!$2:$9,MATCH($B$3,attributes!$A$2:$A$9,0),35) -> 1 | J39: =INDEX(abilities!$1:$1,35) -> shulker_bullet | K39: =INDEX(abilities!$2:$9,MATCH($B$3,abilities!$A$2:$A$9,0),35) -> 1
G40: =INDEX(attributes!$1:$1,36) -> void_cloud | H40: =INDEX(attributes!$2:$9,MATCH($B$3,attributes!$A$2:$A$9,0),36) -> 1 | J40: =INDEX(abilities!$1:$1,36) -> snowball_shot | K40: =INDEX(abilities!$2:$9,MATCH($B$3,abilities!$A$2:$A$9,0),36) -> 1
G41: =INDEX(attributes!$1:$1,37) -> warping_bite | H41: =INDEX(attributes!$2:$9,MATCH($B$3,attributes!$A$2:$A$9,0),37) -> 1 | J41: =INDEX(abilities!$1:$1,37) -> trident | K41: =INDEX(abilities!$2:$9,MATCH($B$3,abilities!$A$2:$A$9,0),37) -> 1
G42: =INDEX(attributes!$1:$1,38) -> witherfang | H42: =INDEX(attributes!$2:$9,MATCH($B$3,attributes!$A$2:$A$9,0),38) -> 1 | J42: =INDEX(abilities!$1:$1,38) -> warden_scream | K42: =INDEX(abilities!$2:$9,MATCH($B$3,abilities!$A$2:$A$9,0),38) -> 1
...

Sheet base_stats
A1: class | B1: armor | C1: armor_toughness | D1: damage | E1: hp | F1: knockback | G1: knockback_resist | H1: speed
A2: assassin | B2: 1 | C2: 1 | D2: 1 | E2: 1 | F2: 1 | G2: 1 | H2: 3.8
A3: attributer | B3: 1 | C3: 1 | D3: 1 | E3: 1 | F3: 1 | G3: 1 | H3: 1
A4: dps | B4: 1 | C4: 1 | D4: 4.3 | E4: 1 | F4: 1 | G4: 1 | H4: 1
A5: mage | B5: 1 | C5: 1 | D5: 1 | E5: 1 | F5: 1 | G5: 1 | H5: 1
A6: maniac | B6: 1 | C6: 1 | D6: 1 | E6: 1 | F6: 1 | G6: 1 | H6: 1
A7: shooter | B7: 1 | C7: 1 | D7: 1 | E7: 1 | F7: 2.8 | G7: 1 | H7: 1.8
A8: supporter | B8: 1 | C8: 1 | D8: 1 | E8: 1 | F8: 1 | G8: 2.8 | H8: 1.8
A9: tanker | B9: 3 | C9: 3 | D9: 1 | E9: 3 | F9: 1 | G9: 1 | H9: 1

Sheet attributes
A1: class | B1: ability_power | C1: amphibious | D1: bane_of_arthropods | E1: blazing_protection | F1: bubbling | G1: chain_lightning | H1: charisma | I1: fire_resistance | J1: firefang | K1: frost_fang | L1: health_siphon | M1: herding | N1: killer | O1: killexploder | P1: lifesteal | Q1: lightningfang | R1: linked_inventory | S1: magnetic | T1: muffled | U1: ore_scenting | V1: pacifist | W1: pierce | X1: poison_fang | Y1: poison_resistance | Z1: positive_effect_steal | AA1: regeneration | AB1: rejuvenation | AC1: resistance | AD1: smite | AE1: speed | AF1: strength | AG1: sweeping_edge | AH1: totem | AI1: victim_siphon | AJ1: void_cloud | AK1: warping_bite | AL1: witherfang
A2: assassin | B2: 1 | C2: 4 | D2: 1 | E2: 1 | F2: 2.5 | G2: 4 | H2: 1 | I2: 1 | J2: 2.6 | K2: 2.6 | L2: 1 | M2: 1 | N2: 4 | O2: 2.5 | P2: 3 | Q2: 1.6 | R2: 1 | S2: 4 | T2: 1.5 | U2: 1 | V2: 1 | W2: 2.5 | X2: 4 | Y2: 1 | Z2: 1 | AA2: 1 | AB2: 4 | AC2: 1 | AD2: 1 | AE2: 3.2 | AF2: 1.4 | AG2: 1 | AH2: 1 | AI2: 4 | AJ2: 2.5 | AK2: 4 | AL2: 3
A3: attributer | B3: 1 | C3: 1 | D3: 1 | E3: 1 | F3: 1 | G3: 1 | H3: 1 | I3: 1 | J3: 1 | K3: 1 | L3: 1 | M3: 1 | N3: 1 | O3: 1 | P3: 1 | Q3: 1 | R3: 1 | S3: 1 | T3: 1 | U3: 1 | V3: 1 | W3: 1 | X3: 1 | Y3: 1 | Z3: 1 | AA3: 1 | AB3: 1 | AC3: 1 | AD3: 1 | AE3: 1 | AF3: 1 | AG3: 1 | AH3: 1 | AI3: 1 | AJ3: 1 | AK3: 1 | AL3: 1
A4: dps | B4: 1 | C4: 1 | D4: 2.5 | E4: 1 | F4: 1 | G4: 1.5 | H4: 1 | I4: 1 | J4: 3 | K4: 2.6 | L4: 1 | M4: 1 | N4: 3.4 | O4: 1 | P4: 1 | Q4: 2.6 | R4: 1 | S4: 1 | T4: 1 | U4: 1 | V4: 1 | W4: 4 | X4: 2.6 | Y4: 1 | Z4: 1 | AA4: 1 | AB4: 1 | AC4: 1 | AD4: 2.5 | AE4: 1 | AF4: 4 | AG4: 4 | AH4: 1 | AI4: 1 | AJ4: 1 | AK4: 1 | AL4: 2.6
A5: mage | B5: 6.2 | C5: 1 | D5: 1 | E5: 1 | F5: 1 | G5: 2.5 | H5: 1 | I5: 1 | J5: 2 | K5: 1 | L5: 1 | M5: 1 | N5: 1 | O5: 1 | P5: 1 | Q5: 3.2 | R5: 1 | S5: 1 | T5: 1 | U5: 1 | V5: 1 | W5: 1 | X5: 1 | Y5: 1 | Z5: 2.6 | AA5: 1 | AB5: 2.5 | AC5: 1 | AD5: 1 | AE5: 1 | AF5: 1 | AG5: 1 | AH5: 1 | AI5: 1 | AJ5: 1 | AK5: 1 | AL5: 2
A6: maniac | B6: 1 | C6: 1 | D6: 1 | E6: 1 | F6: 1 | G6: 1 | H6: 1 | I6: 1 | J6: 1 | K6: 1 | L6: 1 | M6: 1 | N6: 1 | O6: 1 | P6: 1 | Q6: 1 | R6: 1 | S6: 1 | T6: 1 | U6: 1 | V6: 1 | W6: 1 | X6: 1 | Y6: 1 | Z6: 1 | AA6: 1 | AB6: 1 | AC6: 1 | AD6: 1 | AE6: 1 | AF6: 1 | AG6: 1 | AH6: 1 | AI6: 1 | AJ6: 1 | AK6: 1 | AL6: 1
A7: shooter | B7: 1 | C7: 1 | D7: 2.5 | E7: 1 | F7: 1 | G7: 1.5 | H7: 1 | I7: 1 | J7: 3 | K7: 2.6 | L7: 1 | M7: 1 | N7: 3.4 | O7: 1 | P7: 1 | Q7: 2.6 | R7: 1 | S7: 1 | T7: 1 | U7: 1 | V7: 1 | W7: 4 | X7: 2.6 | Y7: 1 | Z7: 1 | AA7: 1 | AB7: 1 | AC7: 1 | AD7: 2.5 | AE7: 3.4 | AF7: 4 | AG7: 4 | AH7: 1 | AI7: 1 | AJ7: 1 | AK7: 1 | AL7: 2.6
A8: supporter | B8: 1 | C8: 1 | D8: 1 | E8: 1 | F8: 1 | G8: 1 | H8: 2.5 | I8: 3.6 | J8: 1 | K8: 1 | L8: 1 | M8: 2.5 | N8: 1 | O8: 1 | P8: 1 | Q8: 1 | R8: 2.5 | S8: 1 | T8: 1 | U8: 2.5 | V8: 1 | W8: 1 | X8: 1 | Y8: 3.6 | Z8: 1 | AA8: 4 | AB8: 1 | AC8: 4.2 | AD8: 1 | AE8: 1 | AF8: 1 | AG8: 1 | AH8: 4.2 | AI8: 1 | AJ8: 1 | AK8: 1 | AL8: 1
A9: tanker | B9: 1 | C9: 1 | D9: 1 | E9: 4 | F9: 1 | G9: 1 | H9: 1 | I9: 3.8 | J9: 1 | K9: 1 | L9: 2.5 | M9: 1 | N9: 1 | O9: 1 | P9: 1 | Q9: 1 | R9: 1 | S9: 1 | T9: 1 | U9: 1 | V9: 2.8 | W9: 1 | X9: 1 | Y9: 3.8 | Z9: 1 | AA9: 4.2 | AB9: 1 | AC9: 4.6 | AD9: 1 | AE9: 1 | AF9: 1 | AG9: 1 | AH9: 3.6 | AI9: 1 | AJ9: 1 | AK9: 1 | AL9: 1

Sheet abilities
A1: class | B1: arrow_shot | C1: battle_strength | D1: battlefield_medic | E1: berserker | F1: blaze_attack | G1: bloodlust | H1: body_block | I1: cleanse_touch | J1: crossbow | K1: dash | L1: defensive_aura | M1: deflection | N1: defusal | O1: dragon_fireball | P1: elder_guardian_beam | Q1: emergency_shield | R1: ender_pearl_jump | S1: evoker_fangs | T1: ghast_fireball | U1: guardian_beam | V1: guardian_intercept | W1: guardian_repulse | X1: healing_aura | Y1: healing_bottle | Z1: immunity_frame | AA1: last_stand_fury | AB1: life_gift | AC1: lightning_strike | AD1: llama_spit | AE1: psychic_wall | AF1: retaliation_slow | AG1: shadow_hands | AH1: shield_block | AI1: shulker_bullet | AJ1: snowball_shot | AK1: trident | AL1: warden_scream | AM1: wither_skull
A2: assassin | B2: 1 | C2: 1 | D2: 1 | E2: 3.2 | F2: 1 | G2: 3.6 | H2: 1 | I2: 1 | J2: 1 | K2: 4 | L2: 1 | M2: 1 | N2: 1 | O2: 1 | P2: 1 | Q2: 1 | R2: 4.2 | S2: 1 | T2: 1 | U2: 1 | V2: 1 | W2: 1 | X2: 1 | Y2: 1 | Z2: 1 | AA2: 1 | AB2: 1 | AC2: 1 | AD2: 1 | AE2: 1 | AF2: 4 | AG2: 1 | AH2: 1 | AI2: 2 | AJ2: 1 | AK2: 1 | AL2: 3.8 | AM2: 2.4
A3: attributer | B3: 1 | C3: 1 | D3: 1 | E3: 1 | F3: 1 | G3: 1 | H3: 1 | I3: 1 | J3: 1 | K3: 1 | L3: 1 | M3: 1 | N3: 1 | O3: 1 | P3: 1 | Q3: 1 | R3: 1 | S3: 1 | T3: 1 | U3: 1 | V3: 1 | W3: 1 | X3: 1 | Y3: 1 | Z3: 1 | AA3: 1 | AB3: 1 | AC3: 1 | AD3: 1 | AE3: 1 | AF3: 1 | AG3: 1 | AH3: 1 | AI3: 1 | AJ3: 1 | AK3: 1 | AL3: 1 | AM3: 1
A4: dps | B4: 1 | C4: 1 | D4: 1 | E4: 4 | F4: 1 | G4: 4 | H4: 1 | I4: 1 | J4: 1 | K4: 1 | L4: 1 | M4: 1 | N4: 1 | O4: 1 | P4: 1 | Q4: 1 | R4: 1 | S4: 1 | T4: 1 | U4: 1 | V4: 1 | W4: 1 | X4: 1 | Y4: 1 | Z4: 1 | AA4: 1 | AB4: 1 | AC4: 1 | AD4: 1 | AE4: 1 | AF4: 1 | AG4: 1 | AH4: 1 | AI4: 1 | AJ4: 1 | AK4: 1 | AL4: 1 | AM4: 1
A5: mage | B5: 1 | C5: 1 | D5: 1 | E5: 1 | F5: 1 | G5: 1 | H5: 1 | I5: 1 | J5: 1 | K5: 1 | L5: 1 | M5: 1 | N5: 1 | O5: 4.6 | P5: 4.2 | Q5: 1 | R5: 1 | S5: 3.6 | T5: 3.2 | U5: 4.4 | V5: 1 | W5: 1 | X5: 1 | Y5: 1 | Z5: 1 | AA5: 1 | AB5: 1 | AC5: 3.6 | AD5: 1 | AE5: 1 | AF5: 1 | AG5: 4 | AH5: 1 | AI5: 4 | AJ5: 1 | AK5: 1 | AL5: 3.8 | AM5: 4
A6: maniac | B6: 1 | C6: 1 | D6: 1 | E6: 1 | F6: 1 | G6: 1 | H6: 1 | I6: 1 | J6: 1 | K6: 1 | L6: 1 | M6: 1 | N6: 1 | O6: 1 | P6: 1 | Q6: 1 | R6: 1 | S6: 1 | T6: 1 | U6: 1 | V6: 1 | W6: 1 | X6: 1 | Y6: 1 | Z6: 1 | AA6: 1 | AB6: 1 | AC6: 1 | AD6: 1 | AE6: 1 | AF6: 1 | AG6: 1 | AH6: 1 | AI6: 1 | AJ6: 1 | AK6: 1 | AL6: 1 | AM6: 1
A7: shooter | B7: 5 | C7: 1 | D7: 1 | E7: 1 | F7: 3.6 | G7: 1 | H7: 1 | I7: 1 | J7: 5.5 | K7: 1 | L7: 1 | M7: 1 | N7: 1 | O7: 1 | P7: 1 | Q7: 1 | R7: 1 | S7: 1 | T7: 1 | U7: 1 | V7: 1 | W7: 1 | X7: 1 | Y7: 1 | Z7: 1 | AA7: 1 | AB7: 1 | AC7: 1 | AD7: 4.2 | AE7: 1 | AF7: 1 | AG7: 1 | AH7: 1 | AI7: 1 | AJ7: 5.8 | AK7: 5.2 | AL7: 1 | AM7: 1
A8: supporter | B8: 1 | C8: 3.2 | D8: 4 | E8: 1 | F8: 1 | G8: 1 | H8: 1 | I8: 4 | J8: 1 | K8: 1 | L8: 4.6 | M8: 1 | N8: 1 | O8: 1 | P8: 1 | Q8: 1 | R8: 1 | S8: 1 | T8: 1 | U8: 1 | V8: 1 | W8: 1 | X8: 10 | Y8: 6 | Z8: 1 | AA8: 1 | AB8: 4 | AC8: 1 | AD8: 1 | AE8: 1 | AF8: 1 | AG8: 1 | AH8: 2.5 | AI8: 1 | AJ8: 1 | AK8: 1 | AL8: 1 | AM8: 1
A9: tanker | B9: 1 | C9: 1 | D9: 1 | E9: 1 | F9: 1 | G9: 1 | H9: 4 | I9: 1 | J9: 1 | K9: 1 | L9: 4.8 | M9: 4 | N9: 7 | O9: 1 | P9: 1 | Q9: 4 | R9: 1 | S9: 1 | T9: 1 | U9: 1 | V9: 4 | W9: 4 | X9: 1 | Y9: 1 | Z9: 4 | AA9: 4 | AB9: 1 | AC9: 1 | AD9: 1 | AE9: 4 | AF9: 1 | AG9: 1 | AH9: 4 | AI9: 1 | AJ9: 1 | AK9: 1 | AL9: 1 | AM9: 1

Sheet meta
A1: key | B1: value
A2: preferredAttributeWeightMultiplier | B2: 30
A3: preferredAbilityWeightMultiplier | B3: 9
A4: defaultCategory.base | B4: 90
A5: defaultCategory.attribute | B5: 10
A6: defaultCategory.ability | B6: 10
A7: defaultBaseStat.armor | B7: 3
A8: defaultBaseStat.armor_toughness | B8: 3
A9: defaultBaseStat.damage | B9: 3
A10: defaultBaseStat.hp | B10: 70
A11: defaultBaseStat.knockback | B11: 3
A12: defaultBaseStat.knockback_resist | B12: 3
A13: defaultBaseStat.speed | B13: 3

Sheet categories
A1: class | B1: base | C1: attribute | D1: ability
A2: assassin | B2: 90 | C2: 10 | D2: 10
A3: attributer | B3: 63.6 | C3: 34.2 | D3: 2.2
A4: dps | B4: 96 | C4: 3 | D4: 1
A5: mage | B5: 85 | C5: 10 | D5: 15
A6: maniac | B6: 65 | C6: 5 | D6: 30
A7: shooter | B7: 85 | C7: 10 | D7: 15
A8: supporter | B8: 85 | C8: 10 | D8: 15
A9: tanker | B9: 90 | C9: 10 | D9: 10
